Workbook

Sheet Paramètres
A1: Budget Food truck
B3: Année | C3: 2025 | D3: =C3+1 -> 2026 | E3: =D3+1 -> 2027
B4: Prix de vente repas moyen TTC | C4: 15 | D4: =C4*1.05 -> 15.75 | E4: =D4*1.05 -> 16.5375
B5: Achat de MP | C5: 0.34 | D5: 0.35 | E5: 0.36
B6: Achat Boissons | C6: 0.24 | D6: 0.25 | E6: 0.26
B7: Prix emballages/vente | C7: 0.27 | D7: =C7 -> 0.27 | E7: =D7 -> 0.27
B8: NB ventes/jour | C8: 50 | D8: =C8*1.1 -> 55 | E8: =D8*1.05 -> 57.75
B9: Distance journalière (km) | C9: 50 | D9: 50 | E9: 50
B10: Coût occupation temporaire | C10: 150 | D10: =C10*1.05 -> 157.5 | E10: =D10*1.05 -> 165.375
B11: Coût carburant / 100 km | C11: 7 | D11: =C11*1.1 -> 7.7 | E11: =D11*1.1 -> 8.47
B12: Coût/km | C12: =C11/100 -> 0.07 | D12: =D11/100 -> 0.077 | E12: =E11/100 -> 0.0847
B13: Achat véhicule | C13: ='Plan de financement initial'!D23 -> 39000
B14: Mois de mise en service | C14: Janvier
B15: Montant emprunt | C15: ='Plan de financement initial'!H30 -> 37000
B16: Taux | C16: 0.035
B17: Durée (ans) | C17: 5

Sheet Trésorerie année 1
A1: Budget de trésorerie | B1: =Paramètres!$C$3 -> 2025
A2: Régime fiscal EURL
A3: Trésorerie début de mois | B3: 0 | C3: =B51 -> 10461.905 | D3: =C51 -> 11693.811 | E3: =D51 -> 13235.716 | F3: =E51 -> 14587.622 | G3: =F51 -> 15939.527 | H3: =G51 -> 17481.433 | I3: =H51 -> 19393.338 | J3: =I51 -> 20935.243 | ... M3: =L51 -> 24254.494
B5: Janvier | C5: Février | D5: Mars | E5: Avril | F5: Mai | G5: Juin | H5: Juillet | I5: Août | J5: Septembre | K5: Octobre | L5: Novembre | M5: Décembre | O5: TOTAL
A6: Nb de jours ouvrables | B6: =NETWORKDAYS(DATE(Paramètres!$C$3,COLUMN()-1,1),EOMONTH(DATE(Paramètres!$C$3,COLUMN()-1,1),0)) -> 23 | C6: =NETWORKDAYS(DATE(Paramètres!$C$3,COLUMN()-1,1),EOMONTH(DATE(Paramètres!$C$3,COLUMN()-1,1),0)) -> 20 | D6: =NETWORKDAYS(DATE(Paramètres!$C$3,COLUMN()-1,1),EOMONTH(DATE(Paramètres!$C$3,COLUMN()-1,1),0)) -> 21 | E6: =NETWORKDAYS(DATE(Paramètres!$C$3,COLUMN()-1,1),EOMONTH(DATE(Paramètres!$C$3,COLUMN()-1,1),0)) -> 22 | F6: =NETWORKDAYS(DATE(Paramètres!$C$3,COLUMN()-1,1),EOMONTH(DATE(Paramètres!$C$3,COLUMN()-1,1),0)) -> 22 | G6: =NETWORKDAYS(DATE(Paramètres!$C$3,COLUMN()-1,1),EOMONTH(DATE(Paramètres!$C$3,COLUMN()-1,1),0)) -> 21 | H6: =NETWORKDAYS(DATE(Paramètres!$C$3,COLUMN()-1,1),EOMONTH(DATE(Paramètres!$C$3,COLUMN()-1,1),0)) -> 23 | I6: =NETWORKDAYS(DATE(Paramètres!$C$3,COLUMN()-1,1),EOMONTH(DATE(Paramètres!$C$3,COLUMN()-1,1),0)) -> 21 | ... M6: =NETWORKDAYS(DATE(Paramètres!$C$3,COLUMN()-1,1),EOMONTH(DATE(Paramètres!$C$3,COLUMN()-1,1),0)) -> 23 | O6: =SUM(B6:M6) -> 261
A7: Ventes repas | B7: =(Paramètres!$C$8*Paramètres!$C$4*'Trésorerie année 1'!B6) -> 17250 | C7: =(Paramètres!$C$8*Paramètres!$C$4*'Trésorerie année 1'!C6) -> 15000 | D7: =(Paramètres!$C$8*Paramètres!$C$4*'Trésorerie année 1'!D6) -> 15750 | E7: =(Paramètres!$C$8*Paramètres!$C$4*'Trésorerie année 1'!E6) -> 16500 | F7: =(Paramètres!$C$8*Paramètres!$C$4*'Trésorerie année 1'!F6) -> 16500 | G7: =(Paramètres!$C$8*Paramètres!$C$4*'Trésorerie année 1'!G6) -> 15750 | H7: =(Paramètres!$C$8*Paramètres!$C$4*'Trésorerie année 1'!H6) -> 17250 | I7: =(Paramètres!$C$8*Paramètres!$C$4*'Trésorerie année 1'!I6) -> 15750 | ... M7: =(Paramètres!$C$8*Paramètres!$C$4*'Trésorerie année 1'!M6) -> 17250 | O7: =SUM(B7:M7) -> 195750
A8: Ventes Boissons | B8: =Paramètres!$C$8*'Trésorerie année 1'!B6*Paramètres!$C$6*3 -> 828 | C8: =Paramètres!$C$8*'Trésorerie année 1'!C6*Paramètres!$C$6*3 -> 720 | D8: =Paramètres!$C$8*'Trésorerie année 1'!D6*Paramètres!$C$6*3 -> 756 | E8: =Paramètres!$C$8*'Trésorerie année 1'!E6*Paramètres!$C$6*3 -> 792 | F8: =Paramètres!$C$8*'Trésorerie année 1'!F6*Paramètres!$C$6*3 -> 792 | G8: =Paramètres!$C$8*'Trésorerie année 1'!G6*Paramètres!$C$6*3 -> 756 | H8: =Paramètres!$C$8*'Trésorerie année 1'!H6*Paramètres!$C$6*3 -> 828 | I8: =Paramètres!$C$8*'Trésorerie année 1'!I6*Paramètres!$C$6*3 -> 756 | ... M8: =Paramètres!$C$8*'Trésorerie année 1'!M6*Paramètres!$C$6*3 -> 828 | O8: =SUM(B8:M8) -> 9396
A9: Apport personnel - associés | B9: ='Plan de financement initial'!H7 -> 22000 | O9: =SUM(B9:M9) -> 22000
A10: Prêts et financements | B10: =Paramètres!$C$15 -> 37000 | O10: =SUM(B10:M10) -> 37000
A11: Aides & Subventions | B11: ='Plan de financement initial'!H16+'Plan de financement initial'!H19+'Plan de financement initial'!H24 -> 0 | O11: =SUM(B11:M11) -> 0
A12: ENCAISSEMENTS | B12: =SUM(B7:B11) -> 77078 | C12: =SUM(C7:C11) -> 15720 | D12: =SUM(D7:D11) -> 16506 | E12: =SUM(E7:E11) -> 17292 | F12: =SUM(F7:F11) -> 17292 | G12: =SUM(G7:G11) -> 16506 | H12: =SUM(H7:H11) -> 18078 | I12: =SUM(I7:I11) -> 16506 | ... M12: =SUM(M7:M11) -> 18078 | O12: =SUM(B12:M12) -> 264146 | P12: =IF(O12=SUM(O7:O11),"ok","non") -> ok
A14: Immobilisations incorporelles | B14: ='Plan de financement initial'!D15+'Plan de financement initial'!D7 -> 2000 | O14: =SUM(B14:M14) -> 2000
A15: Immobilisations corporelles | B15: =Paramètres!$C$13+'Plan de financement initial'!D25 -> 48000 | C15: =IF(C5=Paramètres!$C$14,Paramètres!$C$13,0) -> 0 | D15: =IF(D5=Paramètres!$C$14,Paramètres!$C$13,0) -> 0 | E15: =IF(E5=Paramètres!$C$14,Paramètres!$C$13,0) -> 0 | F15: 0 | G15: =IF(G5=Paramètres!$C$14,Paramètres!$C$13,0) -> 0 | H15: =IF(H5=Paramètres!$C$14,Paramètres!$C$13,0) -> 0 | I15: =IF(I5=Paramètres!$C$14,Paramètres!$C$13,0) -> 0 | J15: =IF(J5=Paramètres!$C$14,Paramètres!$C$13,0) -> 0 | K15: =IF(K5=Paramètres!$C$14,Paramètres!$C$13,0) -> 0 | L15: =IF(L5=Paramètres!$C$14,Paramètres!$C$13,0) -> 0 | M15: =IF(M5=Paramètres!$C$14,Paramètres!$C$13,0) -> 0 | O15: =SUM(B15:M15) -> 48000
A16: IMMOBILISATIONS | B16: =SUM(B14:B15) -> 50000 | C16: =SUM(C14:C15) -> 0 | D16: =SUM(D14:D15) -> 0 | E16: =SUM(E14:E15) -> 0 | F16: =SUM(F14:F15) -> 0 | G16: =SUM(G14:G15) -> 0 | H16: =SUM(H14:H15) -> 0 | I16: =SUM(I14:I15) -> 0 | ... M16: =SUM(M14:M15) -> 0 | O16: =SUM(B16:M16) -> 50000 | P16: =IF(O16=SUM(O14:O15),"ok","non") -> ok
A18: Achats de MP | B18: =B7*Paramètres!$C$5 -> 5865 | C18: =C7*Paramètres!$C$5 -> 5100 | D18: =D7*Paramètres!$C$5 -> 5355 | E18: =E7*Paramètres!$C$5 -> 5610 | F18: =F7*Paramètres!$C$5 -> 5610 | G18: =G7*Paramètres!$C$5 -> 5355 | H18: =H7*Paramètres!$C$5 -> 5865 | I18: =I7*Paramètres!$C$5 -> 5355 | ... M18: =M7*Paramètres!$C$5 -> 5865 | O18: =SUM(B18:M18) -> 66555
A19: Emballages | B19: =Paramètres!$C$7*Paramètres!$C$8*'Trésorerie année 1'!B6 -> 310.5 | C19: =Paramètres!$C$7*Paramètres!$C$8*'Trésorerie année 1'!C6 -> 270 | D19: =Paramètres!$C$7*Paramètres!$C$8*'Trésorerie année 1'!D6 -> 283.5 | E19: =Paramètres!$C$7*Paramètres!$C$8*'Trésorerie année 1'!E6 -> 297 | F19: =Paramètres!$C$7*Paramètres!$C$8*'Trésorerie année 1'!F6 -> 297 | G19: =Paramètres!$C$7*Paramètres!$C$8*'Trésorerie année 1'!G6 -> 283.5 | H19: =Paramètres!$C$7*Paramètres!$C$8*'Trésorerie année 1'!H6 -> 310.5 | I19: =Paramètres!$C$7*Paramètres!$C$8*'Trésorerie année 1'!I6 -> 283.5 | ... M19: =Paramètres!$C$7*Paramètres!$C$8*'Trésorerie année 1'!M6 -> 310.5 | O19: =SUM(B19:M19) -> 3523.5
A20: Carburant | B20: =Paramètres!$C$9*Paramètres!$C$12*'Trésorerie année 1'!B6 -> 80.5 | C20: =Paramètres!$C$9*Paramètres!$C$12*'Trésorerie année 1'!C6 -> 70 | D20: =Paramètres!$C$9*Paramètres!$C$12*'Trésorerie année 1'!D6 -> 73.5 | E20: =Paramètres!$C$9*Paramètres!$C$12*'Trésorerie année 1'!E6 -> 77 | F20: =Paramètres!$C$9*Paramètres!$C$12*'Trésorerie année 1'!F6 -> 77 | G20: =Paramètres!$C$9*Paramètres!$C$12*'Trésorerie année 1'!G6 -> 73.5 | H20: =Paramètres!$C$9*Paramètres!$C$12*'Trésorerie année 1'!H6 -> 80.5 | I20: =Paramètres!$C$9*Paramètres!$C$12*'Trésorerie année 1'!I6 -> 73.5 | ... M20: =Paramètres!$C$9*Paramètres!$C$12*'Trésorerie année 1'!M6 -> 80.5 | O20: =SUM(B20:M20) -> 913.5
A21: Achats marchandises (boissons) | B21: =B8*Paramètres!$C$6 -> 198.72 | C21: =C8*Paramètres!$C$6 -> 172.8 | D21: =D8*Paramètres!$C$6 -> 181.44 | E21: =E8*Paramètres!$C$6 -> 190.08 | F21: =F8*Paramètres!$C$6 -> 190.08 | G21: =G8*Paramètres!$C$6 -> 181.44 | H21: =H8*Paramètres!$C$6 -> 198.72 | I21: =I8*Paramètres!$C$6 -> 181.44 | ... M21: =M8*Paramètres!$C$6 -> 198.72 | O21: =SUM(B21:M21) -> 2255.04
A22: Fluides (eau, électricité, gaz, etc.) | B22: =B7*0.05 -> 862.5 | C22: =C7*0.05 -> 750 | D22: =D7*0.05 -> 787.5 | E22: =E7*0.05 -> 825 | F22: =F7*0.05 -> 825 | G22: =G7*0.05 -> 787.5 | H22: =H7*0.05 -> 862.5 | I22: =I7*0.05 -> 787.5 | ... M22: =M7*0.05 -> 862.5 | O22: =SUM(B22:M22) -> 9787.5
A23: Frais d'emplacement (AOT) | B23: =Paramètres!$C$10*'Trésorerie année 1'!B6 -> 3450 | C23: =Paramètres!$C$10*'Trésorerie année 1'!C6 -> 3000 | D23: =Paramètres!$C$10*'Trésorerie année 1'!D6 -> 3150 | E23: =Paramètres!$C$10*'Trésorerie année 1'!E6 -> 3300 | F23: =Paramètres!$C$10*'Trésorerie année 1'!F6 -> 3300 | G23: =Paramètres!$C$10*'Trésorerie année 1'!G6 -> 3150 | H23: =Paramètres!$C$10*'Trésorerie année 1'!H6 -> 3450 | I23: =Paramètres!$C$10*'Trésorerie année 1'!I6 -> 3150 | ... M23: =Paramètres!$C$10*'Trésorerie année 1'!M6 -> 3450 | O23: =SUM(B23:M23) -> 39150
A24: Loyer local labo | B24: 500 | C24: 500 | D24: 500 | E24: 500 | F24: 500 | G24: 500 | H24: 500 | I24: 500 | J24: 500 | K24: 500 | L24: 500 | M24: 500 | O24: =SUM(B24:M24) -> 6000
A25: Frais internet-téléphone | B25: =20 -> 20 | C25: 20 | D25: 20 | E25: 20 | F25: 20 | G25: 20 | H25: 20 | I25: 20 | J25: 20 | K25: 20 | L25: 20 | M25: 20 | O25: =SUM(B25:M25) -> 240
A26: Frais logiciel TPE | B26: =(B7+B8)*0.01 -> 180.78 | C26: =(C7+C8)*0.01 -> 157.2 | D26: =(D7+D8)*0.01 -> 165.06 | E26: =(E7+E8)*0.01 -> 172.92 | F26: =(F7+F8)*0.01 -> 172.92 | G26: =(G7+G8)*0.01 -> 165.06 | H26: =(H7+H8)*0.01 -> 180.78 | I26: =(I7+I8)*0.01 -> 165.06 | ... M26: =(M7+M8)*0.01 -> 180.78 | O26: =SUM(B26:M26) -> 2051.46
A27: Fournitures diverses | B27: 700 | E27: 500 | H27: 250 | K27: 250 | O27: =SUM(B27:M27) -> 1700
A28: Entretien / Maintenance | B28: 150 | C28: 150 | D28: 150 | E28: 150 | F28: 150 | G28: 150 | H28: 150 | I28: 150 | J28: 150 | K28: 150 | L28: 150 | M28: 150 | O28: =SUM(B28:M28) -> 1800
A29: Assurances (camion, local, RC) | B29: 225 | C29: 225 | D29: 225 | E29: 225 | F29: 225 | G29: 225 | H29: 225 | I29: 225 | J29: 225 | K29: 225 | L29: 225 | M29: 225 | O29: =SUM(B29:M29) -> 2700
A30: Publicité / Communication / Mkgt | F30: 500 | J30: 500 | O30: =SUM(B30:M30) -> 1000
A31: Honoraires (prestataires divers) | B31: =100 -> 100 | C31: 100 | D31: 100 | E31: 100 | F31: 100 | G31: 100 | H31: 100 | I31: 100 | J31: 100 | K31: 100 | L31: 100 | M31: 100 | O31: =SUM(B31:M31) -> 1200
A32: Mutuelle | B32: 100 | C32: 100 | D32: 100 | E32: 100 | F32: 100 | G32: 100 | H32: 100 | I32: 100 | J32: 100 | K32: 100 | L32: 100 | M32: 100 | O32: =SUM(B32:M32) -> 1200
A33: Salaires Bruts Gérant | B33: 2200 | C33: 2200 | D33: 2200 | E33: 2200 | F33: 2200 | G33: 2200 | H33: 2200 | I33: 2200 | J33: 2200 | K33: 2200 | L33: 2200 | M33: 2200 | O33: =SUM(B33:M33) -> 26400
A34: Charges sociales patronales Gérant | B34: =B33*0.45 -> 990 | C34: =C33*0.45 -> 990 | D34: =D33*0.45 -> 990 | E34: =E33*0.45 -> 990 | F34: =F33*0.45 -> 990 | G34: =G33*0.45 -> 990 | H34: =H33*0.45 -> 990 | I34: =I33*0.45 -> 990 | ... M34: =M33*0.45 -> 990 | O34: =SUM(B34:M34) -> 11880
A35: Frais financiers (frais TC, î) | B35: 10 | C35: 10 | D35: 10 | E35: 10 | F35: 10 | G35: 10 | H35: 10 | I35: 10 | J35: 10 | K35: 10 | L35: 10 | M35: 10 | O35: =SUM(B35:M35) -> 120
A36: Échéances d'emprunt | B36: =IF(Paramètres!$C$15="",0,-PMT(Paramètres!$C$16/12,Paramètres!$C$17*12,Paramètres!$C$15)) -> 673.09456 | C36: =IF(Paramètres!$C$15="",0,-PMT(Paramètres!$C$16/12,Paramètres!$C$17*12,Paramètres!$C$15)) -> 673.09456 | D36: =IF(Paramètres!$C$15="",0,-PMT(Paramètres!$C$16/12,Paramètres!$C$17*12,Paramètres!$C$15)) -> 673.09456 | E36: =IF(Paramètres!$C$15="",0,-PMT(Paramètres!$C$16/12,Paramètres!$C$17*12,Paramètres!$C$15)) -> 673.09456 | F36: =IF(Paramètres!$C$15="",0,-PMT(Paramètres!$C$16/12,Paramètres!$C$17*12,Paramètres!$C$15)) -> 673.09456 | G36: =IF(Paramètres!$C$15="",0,-PMT(Paramètres!$C$16/12,Paramètres!$C$17*12,Paramètres!$C$15)) -> 673.09456 | H36: =IF(Paramètres!$C$15="",0,-PMT(Paramètres!$C$16/12,Paramètres!$C$17*12,Paramètres!$C$15)) -> 673.09456 | I36: =IF(Paramètres!$C$15="",0,-PMT(Paramètres!$C$16/12,Paramètres!$C$17*12,Paramètres!$C$15)) -> 673.09456 | ... M36: =IF(Paramètres!$C$15="",0,-PMT(Paramètres!$C$16/12,Paramètres!$C$17*12,Paramètres!$C$15)) -> 673.09456 | O36: =SUM(B36:M36) -> 8077.1348
A37: IS ou autres selon régime jurid | O37: =SUM(B37:M37) -> 0
A38: DECAISSEMENTS | B38: =SUM(B18:B37) -> 16616.095 | C38: =SUM(C18:C37) -> 14488.095 | D38: =SUM(D18:D37) -> 14964.095 | E38: =SUM(E18:E37) -> 15940.095 | F38: =SUM(F18:F37) -> 15940.095 | G38: =SUM(G18:G37) -> 14964.095 | H38: =SUM(H18:H37) -> 16166.095 | I38: =SUM(I18:I37) -> 14964.095 | ... M38: =SUM(M18:M37) -> 15916.095 | O38: =SUM(B38:M38) -> 186553.13 | P38: =IF(O38=SUM(O18:O37),"ok","non") -> ok
A40: TVA collectée 20% | B40: =B8/1.2*0.2*0.25 -> 34.5 | C40: =C8/1.2*0.2*0.25 -> 30 | D40: =D8/1.2*0.2*0.25 -> 31.5 | E40: =E8/1.2*0.2*0.25 -> 33 | F40: =F8/1.2*0.2*0.25 -> 33 | G40: =G8/1.2*0.2*0.25 -> 31.5 | H40: =H8/1.2*0.2*0.25 -> 34.5 | I40: =I8/1.2*0.2*0.25 -> 31.5 | ... M40: =M8/1.2*0.2*0.25 -> 34.5 | O40: =SUM(B40:M40) -> 391.5
A41: TVA Collectée 10% | B41: =B7/1.1*0.1+B8/1.1*0.1*0.75 -> 1624.6364 | C41: =C7/1.1*0.1+C8/1.1*0.1*0.75 -> 1412.7273 | D41: =D7/1.1*0.1+D8/1.1*0.1*0.75 -> 1483.3636 | E41: =E7/1.1*0.1+E8/1.1*0.1*0.75 -> 1554 | F41: =F7/1.1*0.1+F8/1.1*0.1*0.75 -> 1554 | G41: =G7/1.1*0.1+G8/1.1*0.1*0.75 -> 1483.3636 | H41: =H7/1.1*0.1+H8/1.1*0.1*0.75 -> 1624.6364 | I41: =I7/1.1*0.1+I8/1.1*0.1*0.75 -> 1483.3636 | ... M41: =M7/1.1*0.1+M8/1.1*0.1*0.75 -> 1624.6364 | O41: =SUM(B41:M41) -> 18436.091
A42: TVA collectée 5,5% | O42: =SUM(B42:M42) -> 0
A43: TVA déductible 20% | B43: =(B16/1.2*0.2)+(B19/1.2*0.2)+(B20/1.2*0.2)+(B21/1.2*0.2*0.25)+(B22/1.2*0.2)+(B25/1.2*0.2)+(B26/1.2*0.2)+(B27/1.2*0.2)+(B28/1.2*0.2)+(B30/1.2*0.2)+(B31/1.2*0.2) -> 8742.3267 | C43: =(C16/1.2*0.2)+(C19/1.2*0.2)+(C20/1.2*0.2)+(C21/1.2*0.2*0.25)+(C22/1.2*0.2)+(C25/1.2*0.2)+(C26/1.2*0.2)+(C27/1.2*0.2)+(C28/1.2*0.2)+(C30/1.2*0.2)+(C31/1.2*0.2) -> 260.06667 | D43: =(D16/1.2*0.2)+(D19/1.2*0.2)+(D20/1.2*0.2)+(D21/1.2*0.2*0.25)+(D22/1.2*0.2)+(D25/1.2*0.2)+(D26/1.2*0.2)+(D27/1.2*0.2)+(D28/1.2*0.2)+(D30/1.2*0.2)+(D31/1.2*0.2) -> 270.82 | E43: =(E16/1.2*0.2)+(E19/1.2*0.2)+(E20/1.2*0.2)+(E21/1.2*0.2*0.25)+(E22/1.2*0.2)+(E25/1.2*0.2)+(E26/1.2*0.2)+(E27/1.2*0.2)+(E28/1.2*0.2)+(E30/1.2*0.2)+(E31/1.2*0.2) -> 364.90667 | F43: =(F16/1.2*0.2)+(F19/1.2*0.2)+(F20/1.2*0.2)+(F21/1.2*0.2*0.25)+(F22/1.2*0.2)+(F25/1.2*0.2)+(F26/1.2*0.2)+(F27/1.2*0.2)+(F28/1.2*0.2)+(F30/1.2*0.2)+(F31/1.2*0.2) -> 364.90667 | G43: =(G16/1.2*0.2)+(G19/1.2*0.2)+(G20/1.2*0.2)+(G21/1.2*0.2*0.25)+(G22/1.2*0.2)+(G25/1.2*0.2)+(G26/1.2*0.2)+(G27/1.2*0.2)+(G28/1.2*0.2)+(G30/1.2*0.2)+(G31/1.2*0.2) -> 270.82 | H43: =(H16/1.2*0.2)+(H19/1.2*0.2)+(H20/1.2*0.2)+(H21/1.2*0.2*0.25)+(H22/1.2*0.2)+(H25/1.2*0.2)+(H26/1.2*0.2)+(H27/1.2*0.2)+(H28/1.2*0.2)+(H30/1.2*0.2)+(H31/1.2*0.2) -> 333.99333 | I43: =(I16/1.2*0.2)+(I19/1.2*0.2)+(I20/1.2*0.2)+(I21/1.2*0.2*0.25)+(I22/1.2*0.2)+(I25/1.2*0.2)+(I26/1.2*0.2)+(I27/1.2*0.2)+(I28/1.2*0.2)+(I30/1.2*0.2)+(I31/1.2*0.2) -> 270.82 | ... M43: =(M16/1.2*0.2)+(M19/1.2*0.2)+(M20/1.2*0.2)+(M21/1.2*0.2*0.25)+(M22/1.2*0.2)+(M25/1.2*0.2)+(M26/1.2*0.2)+(M27/1.2*0.2)+(M28/1.2*0.2)+(M30/1.2*0.2)+(M31/1.2*0.2) -> 292.32667 | O43: =SUM(B43:M43) -> 12129.953
A44: TVA Déductible 10% | O44: =SUM(B44:M44) -> 0
...

Sheet Trésorerie année 2
A1: Budget de trésorerie | B1: =Paramètres!D3 -> 2026
A2: Régime fiscal EURL
A3: Trésorerie début de mois | B3: ='Trésorerie année 1'!M51 -> 25506.372 | C3: =B51 -> 26115.808 | D3: =C51 -> 27018.152 | E3: =D51 -> 28219.244 | F3: =E51 -> 29644.08 | G3: =F51 -> 30911.836 | H3: =G51 -> 32558.133 | I3: =H51 -> 34265.048 | J3: =I51 -> 34978.011 | ... M3: =L51 -> 39316.9
B5: Janvier | C5: Février | D5: Mars | E5: Avril | F5: Mai | G5: Juin | H5: Juillet | I5: Août | J5: Septembre | K5: Octobre | L5: Novembre | M5: Décembre | O5: TOTAL
A6: Nb de jours ouvrables | B6: =NETWORKDAYS(DATE(Paramètres!$D$3,COLUMN()-1,1),EOMONTH(DATE(Paramètres!$D$3,COLUMN()-1,1),0)) -> 22 | C6: =NETWORKDAYS(DATE(Paramètres!$D$3,COLUMN()-1,1),EOMONTH(DATE(Paramètres!$D$3,COLUMN()-1,1),0)) -> 20 | D6: =NETWORKDAYS(DATE(Paramètres!$D$3,COLUMN()-1,1),EOMONTH(DATE(Paramètres!$D$3,COLUMN()-1,1),0)) -> 22 | E6: =NETWORKDAYS(DATE(Paramètres!$D$3,COLUMN()-1,1),EOMONTH(DATE(Paramètres!$D$3,COLUMN()-1,1),0)) -> 22 | F6: =NETWORKDAYS(DATE(Paramètres!$D$3,COLUMN()-1,1),EOMONTH(DATE(Paramètres!$D$3,COLUMN()-1,1),0)) -> 21 | G6: =NETWORKDAYS(DATE(Paramètres!$D$3,COLUMN()-1,1),EOMONTH(DATE(Paramètres!$D$3,COLUMN()-1,1),0)) -> 22 | H6: =NETWORKDAYS(DATE(Paramètres!$D$3,COLUMN()-1,1),EOMONTH(DATE(Paramètres!$D$3,COLUMN()-1,1),0)) -> 23 | I6: =NETWORKDAYS(DATE(Paramètres!$D$3,COLUMN()-1,1),EOMONTH(DATE(Paramètres!$D$3,COLUMN()-1,1),0)) -> 21 | ... M6: =NETWORKDAYS(DATE(Paramètres!$D$3,COLUMN()-1,1),EOMONTH(DATE(Paramètres!$D$3,COLUMN()-1,1),0)) -> 23 | O6: =SUM(B6:M6) -> 261
A7: Ventes repas | B7: =(Paramètres!$D$8*Paramètres!$D$4*'Trésorerie année 2'!B6) -> 19057.5 | C7: =(Paramètres!$D$8*Paramètres!$D$4*'Trésorerie année 2'!C6) -> 17325 | D7: =(Paramètres!$D$8*Paramètres!$D$4*'Trésorerie année 2'!D6) -> 19057.5 | E7: =(Paramètres!$D$8*Paramètres!$D$4*'Trésorerie année 2'!E6) -> 19057.5 | F7: =(Paramètres!$D$8*Paramètres!$D$4*'Trésorerie année 2'!F6) -> 18191.25 | G7: =(Paramètres!$D$8*Paramètres!$D$4*'Trésorerie année 2'!G6) -> 19057.5 | H7: =(Paramètres!$D$8*Paramètres!$D$4*'Trésorerie année 2'!H6) -> 19923.75 | I7: =(Paramètres!$D$8*Paramètres!$D$4*'Trésorerie année 2'!I6) -> 18191.25 | ... M7: =(Paramètres!$D$8*Paramètres!$D$4*'Trésorerie année 2'!M6) -> 19923.75 | O7: =SUM(B7:M7) -> 226091.25
A8: Ventes Boissons | B8: =Paramètres!$D$8*'Trésorerie année 2'!B6*Paramètres!$D$6*3 -> 907.5 | C8: =Paramètres!$D$8*'Trésorerie année 2'!C6*Paramètres!$D$6*3 -> 825 | D8: =Paramètres!$D$8*'Trésorerie année 2'!D6*Paramètres!$D$6*3 -> 907.5 | E8: =Paramètres!$D$8*'Trésorerie année 2'!E6*Paramètres!$D$6*3 -> 907.5 | F8: =Paramètres!$D$8*'Trésorerie année 2'!F6*Paramètres!$D$6*3 -> 866.25 | G8: =Paramètres!$D$8*'Trésorerie année 2'!G6*Paramètres!$D$6*3 -> 907.5 | H8: =Paramètres!$D$8*'Trésorerie année 2'!H6*Paramètres!$D$6*3 -> 948.75 | I8: =Paramètres!$D$8*'Trésorerie année 2'!I6*Paramètres!$D$6*3 -> 866.25 | ... M8: =Paramètres!$D$8*'Trésorerie année 2'!M6*Paramètres!$D$6*3 -> 948.75 | O8: =SUM(B8:M8) -> 10766.25
A9: Apport personnel - associés | B9: 0 | O9: =SUM(B9:M9) -> 0
A10: Prêts et financements | B10: 0 | O10: =SUM(B10:M10) -> 0
A11: Aides & Subventions | B11: ='Plan de financement initial'!H16+'Plan de financement initial'!H19+'Plan de financement initial'!H24 -> 0 | O11: =SUM(B11:M11) -> 0
A12: ENCAISSEMENTS | B12: =SUM(B7:B11) -> 19965 | C12: =SUM(C7:C11) -> 18150 | D12: =SUM(D7:D11) -> 19965 | E12: =SUM(E7:E11) -> 19965 | F12: =SUM(F7:F11) -> 19057.5 | G12: =SUM(G7:G11) -> 19965 | H12: =SUM(H7:H11) -> 20872.5 | I12: =SUM(I7:I11) -> 19057.5 | ... M12: =SUM(M7:M11) -> 20872.5 | O12: =SUM(B12:M12) -> 236857.5 | P12: =IF(O12=SUM(O7:O11),"ok","non") -> ok
A14: Immobilisations incorporelles | B14: 0 | C14: 0 | D14: 0 | E14: 0 | F14: 0 | G14: 0 | H14: 0 | I14: 0 | J14: 0 | K14: 0 | L14: 0 | M14: 0 | O14: =SUM(B14:M14) -> 0
A15: Immobilisations corporelles | B15: 0 | C15: =IF(C5=Paramètres!$C$14,Paramètres!$C$13,0) -> 0 | D15: =IF(D5=Paramètres!$C$14,Paramètres!$C$13,0) -> 0 | E15: =IF(E5=Paramètres!$C$14,Paramètres!$C$13,0) -> 0 | F15: 0 | G15: =IF(G5=Paramètres!$C$14,Paramètres!$C$13,0) -> 0 | H15: =IF(H5=Paramètres!$C$14,Paramètres!$C$13,0) -> 0 | I15: =IF(I5=Paramètres!$C$14,Paramètres!$C$13,0) -> 0 | J15: =IF(J5=Paramètres!$C$14,Paramètres!$C$13,0) -> 0 | K15: =IF(K5=Paramètres!$C$14,Paramètres!$C$13,0) -> 0 | L15: =IF(L5=Paramètres!$C$14,Paramètres!$C$13,0) -> 0 | M15: =IF(M5=Paramètres!$C$14,Paramètres!$C$13,0) -> 0 | O15: =SUM(B15:M15) -> 0
A16: IMMOBILISATIONS | B16: =SUM(B14:B15) -> 0 | C16: =SUM(C14:C15) -> 0 | D16: =SUM(D14:D15) -> 0 | E16: =SUM(E14:E15) -> 0 | F16: =SUM(F14:F15) -> 0 | G16: =SUM(G14:G15) -> 0 | H16: =SUM(H14:H15) -> 0 | I16: =SUM(I14:I15) -> 0 | ... M16: =SUM(M14:M15) -> 0 | O16: =SUM(B16:M16) -> 0 | P16: =IF(O16=SUM(O14:O15),"ok","non") -> ok
A18: Achats de MP | B18: =B7*Paramètres!$D$5 -> 6670.125 | C18: =C7*Paramètres!$D$5 -> 6063.75 | D18: =D7*Paramètres!$D$5 -> 6670.125 | E18: =E7*Paramètres!$D$5 -> 6670.125 | F18: =F7*Paramètres!$D$5 -> 6366.9375 | G18: =G7*Paramètres!$D$5 -> 6670.125 | H18: =H7*Paramètres!$D$5 -> 6973.3125 | I18: =I7*Paramètres!$D$5 -> 6366.9375 | ... M18: =M7*Paramètres!$D$5 -> 6973.3125 | O18: =SUM(B18:M18) -> 79131.938
A19: Emballages | B19: =Paramètres!$D$7*Paramètres!$D$8*'Trésorerie année 2'!B6 -> 326.7 | C19: =Paramètres!$D$7*Paramètres!$D$8*'Trésorerie année 2'!C6 -> 297 | D19: =Paramètres!$D$7*Paramètres!$D$8*'Trésorerie année 2'!D6 -> 326.7 | E19: =Paramètres!$D$7*Paramètres!$D$8*'Trésorerie année 2'!E6 -> 326.7 | F19: =Paramètres!$D$7*Paramètres!$D$8*'Trésorerie année 2'!F6 -> 311.85 | G19: =Paramètres!$D$7*Paramètres!$D$8*'Trésorerie année 2'!G6 -> 326.7 | H19: =Paramètres!$D$7*Paramètres!$D$8*'Trésorerie année 2'!H6 -> 341.55 | I19: =Paramètres!$D$7*Paramètres!$D$8*'Trésorerie année 2'!I6 -> 311.85 | ... M19: =Paramètres!$D$7*Paramètres!$D$8*'Trésorerie année 2'!M6 -> 341.55 | O19: =SUM(B19:M19) -> 3875.85
A20: Carburant | B20: =Paramètres!$D$9*Paramètres!$D$12*'Trésorerie année 2'!B6 -> 84.7 | C20: =Paramètres!$D$9*Paramètres!$D$12*'Trésorerie année 2'!C6 -> 77 | D20: =Paramètres!$D$9*Paramètres!$D$12*'Trésorerie année 2'!D6 -> 84.7 | E20: =Paramètres!$D$9*Paramètres!$D$12*'Trésorerie année 2'!E6 -> 84.7 | F20: =Paramètres!$D$9*Paramètres!$D$12*'Trésorerie année 2'!F6 -> 80.85 | G20: =Paramètres!$D$9*Paramètres!$D$12*'Trésorerie année 2'!G6 -> 84.7 | H20: =Paramètres!$D$9*Paramètres!$D$12*'Trésorerie année 2'!H6 -> 88.55 | I20: =Paramètres!$D$9*Paramètres!$D$12*'Trésorerie année 2'!I6 -> 80.85 | ... M20: =Paramètres!$D$9*Paramètres!$D$12*'Trésorerie année 2'!M6 -> 88.55 | O20: =SUM(B20:M20) -> 1004.85
A21: Achats marchandises (boissons) | B21: =B8*Paramètres!$D$6 -> 226.875 | C21: =C8*Paramètres!$D$6 -> 206.25 | D21: =D8*Paramètres!$D$6 -> 226.875 | E21: =E8*Paramètres!$D$6 -> 226.875 | F21: =F8*Paramètres!$D$6 -> 216.5625 | G21: =G8*Paramètres!$D$6 -> 226.875 | H21: =H8*Paramètres!$D$6 -> 237.1875 | I21: =I8*Paramètres!$D$6 -> 216.5625 | ... M21: =M8*Paramètres!$D$6 -> 237.1875 | O21: =SUM(B21:M21) -> 2691.5625
A22: Fluides (eau, électricité, gaz, etc.) | B22: =B7*0.05 -> 952.875 | C22: =C7*0.05 -> 866.25 | D22: =D7*0.05 -> 952.875 | E22: =E7*0.05 -> 952.875 | F22: =F7*0.05 -> 909.5625 | G22: =G7*0.05 -> 952.875 | H22: =H7*0.05 -> 996.1875 | I22: =I7*0.05 -> 909.5625 | ... M22: =M7*0.05 -> 996.1875 | O22: =SUM(B22:M22) -> 11304.563
A23: Frais d'emplacement (AOT) | B23: =Paramètres!$D$10*'Trésorerie année 2'!B6 -> 3465 | C23: =Paramètres!$D$10*'Trésorerie année 2'!C6 -> 3150 | D23: =Paramètres!$D$10*'Trésorerie année 2'!D6 -> 3465 | E23: =Paramètres!$D$10*'Trésorerie année 2'!E6 -> 3465 | F23: =Paramètres!$D$10*'Trésorerie année 2'!F6 -> 3307.5 | G23: =Paramètres!$D$10*'Trésorerie année 2'!G6 -> 3465 | H23: =Paramètres!$D$10*'Trésorerie année 2'!H6 -> 3622.5 | I23: =Paramètres!$D$10*'Trésorerie année 2'!I6 -> 3307.5 | ... M23: =Paramètres!$D$10*'Trésorerie année 2'!M6 -> 3622.5 | O23: =SUM(B23:M23) -> 41107.5
A24: Loyer local labo | B24: 500 | C24: 500 | D24: 500 | E24: 500 | F24: 500 | G24: 500 | H24: 500 | I24: 500 | J24: 500 | K24: 500 | L24: 500 | M24: 500 | O24: =SUM(B24:M24) -> 6000
A25: Frais internet-téléphone | B25: =20 -> 20 | C25: 20 | D25: 20 | E25: 20 | F25: 20 | G25: 20 | H25: 20 | I25: 20 | J25: 20 | K25: 20 | L25: 20 | M25: 20 | O25: =SUM(B25:M25) -> 240
A26: Frais logiciel TPE | B26: =(B7+B8)*0.01 -> 199.65 | C26: =(C7+C8)*0.01 -> 181.5 | D26: =(D7+D8)*0.01 -> 199.65 | E26: =(E7+E8)*0.01 -> 199.65 | F26: =(F7+F8)*0.01 -> 190.575 | G26: =(G7+G8)*0.01 -> 199.65 | H26: =(H7+H8)*0.01 -> 208.725 | I26: =(I7+I8)*0.01 -> 190.575 | ... M26: =(M7+M8)*0.01 -> 208.725 | O26: =SUM(B26:M26) -> 2368.575
A27: Fournitures diverses | B27: 250 | E27: 250 | H27: 250 | K27: 250 | O27: =SUM(B27:M27) -> 1000
A28: Entretien / Maintenance | B28: 150 | C28: 150 | D28: 150 | E28: 150 | F28: 150 | G28: 150 | H28: 150 | I28: 150 | J28: 150 | K28: 150 | L28: 150 | M28: 150 | O28: =SUM(B28:M28) -> 1800
A29: Assurances (camion, local, RC) | B29: 225 | C29: 225 | D29: 225 | E29: 225 | F29: 225 | G29: 225 | H29: 225 | I29: 225 | J29: 225 | K29: 225 | L29: 225 | M29: 225 | O29: =SUM(B29:M29) -> 2700
A30: Publicité / Communication / Mkgt | D30: 500 | I30: 500 | O30: =SUM(B30:M30) -> 1000
A31: Honoraires (prestataires divers) | B31: =100 -> 100 | C31: 100 | D31: 100 | E31: 100 | F31: 100 | G31: 100 | H31: 100 | I31: 100 | J31: 100 | K31: 100 | L31: 100 | M31: 100 | O31: =SUM(B31:M31) -> 1200
A32: Mutuelle | B32: 100 | C32: 100 | D32: 100 | E32: 100 | F32: 100 | G32: 100 | H32: 100 | I32: 100 | J32: 100 | K32: 100 | L32: 100 | M32: 100 | O32: =SUM(B32:M32) -> 1200
A33: Salaires Bruts Gérant | B33: ='Trésorerie année 1'!B33*1.1 -> 2420 | C33: ='Trésorerie année 1'!C33*1.1 -> 2420 | D33: ='Trésorerie année 1'!D33*1.1 -> 2420 | E33: ='Trésorerie année 1'!E33*1.1 -> 2420 | F33: ='Trésorerie année 1'!F33*1.1 -> 2420 | G33: ='Trésorerie année 1'!G33*1.1 -> 2420 | H33: ='Trésorerie année 1'!H33*1.1 -> 2420 | I33: ='Trésorerie année 1'!I33*1.1 -> 2420 | ... M33: ='Trésorerie année 1'!M33*1.1 -> 2420 | O33: =SUM(B33:M33) -> 29040
A34: Charges sociales patronales Gérant | B34: =B33*0.45 -> 1089 | C34: =C33*0.45 -> 1089 | D34: =D33*0.45 -> 1089 | E34: =E33*0.45 -> 1089 | F34: =F33*0.45 -> 1089 | G34: =G33*0.45 -> 1089 | H34: =H33*0.45 -> 1089 | I34: =I33*0.45 -> 1089 | ... M34: =M33*0.45 -> 1089 | O34: =SUM(B34:M34) -> 13068
A35: Frais financiers (frais TC, î) | B35: 10 | C35: 10 | D35: 10 | E35: 10 | F35: 10 | G35: 10 | H35: 10 | I35: 10 | J35: 10 | K35: 10 | L35: 10 | M35: 10 | O35: =SUM(B35:M35) -> 120
A36: Échéances d'emprunt | B36: =IF(Paramètres!$C$15="",0,-PMT(Paramètres!$C$16/12,Paramètres!$C$17*12,Paramètres!$C$15)) -> 673.09456 | C36: =IF(Paramètres!$C$15="",0,-PMT(Paramètres!$C$16/12,Paramètres!$C$17*12,Paramètres!$C$15)) -> 673.09456 | D36: =IF(Paramètres!$C$15="",0,-PMT(Paramètres!$C$16/12,Paramètres!$C$17*12,Paramètres!$C$15)) -> 673.09456 | E36: =IF(Paramètres!$C$15="",0,-PMT(Paramètres!$C$16/12,Paramètres!$C$17*12,Paramètres!$C$15)) -> 673.09456 | F36: =IF(Paramètres!$C$15="",0,-PMT(Paramètres!$C$16/12,Paramètres!$C$17*12,Paramètres!$C$15)) -> 673.09456 | G36: =IF(Paramètres!$C$15="",0,-PMT(Paramètres!$C$16/12,Paramètres!$C$17*12,Paramètres!$C$15)) -> 673.09456 | H36: =IF(Paramètres!$C$15="",0,-PMT(Paramètres!$C$16/12,Paramètres!$C$17*12,Paramètres!$C$15)) -> 673.09456 | I36: =IF(Paramètres!$C$15="",0,-PMT(Paramètres!$C$16/12,Paramètres!$C$17*12,Paramètres!$C$15)) -> 673.09456 | ... M36: =IF(Paramètres!$C$15="",0,-PMT(Paramètres!$C$16/12,Paramètres!$C$17*12,Paramètres!$C$15)) -> 673.09456 | O36: =SUM(B36:M36) -> 8077.1348
A37: IS ou autres selon régime jurid | B37: ='CR pluriannuel '!D11 -> 839.26302 | O37: =SUM(B37:M37) -> 839.26302
A38: DECAISSEMENTS | B38: =SUM(B18:B37) -> 18302.283 | C38: =SUM(C18:C37) -> 16128.845 | D38: =SUM(D18:D37) -> 17713.02 | E38: =SUM(E18:E37) -> 17463.02 | F38: =SUM(F18:F37) -> 16670.932 | G38: =SUM(G18:G37) -> 17213.02 | H38: =SUM(H18:H37) -> 18005.107 | I38: =SUM(I18:I37) -> 17170.932 | ... M38: =SUM(M18:M37) -> 17755.107 | O38: =SUM(B38:M38) -> 207769.24 | P38: =IF(O38=SUM(O18:O37),"ok","non") -> ok
A40: TVA collectée 20% | B40: =B8/1.2*0.2*0.25 -> 37.8125 | C40: =C8/1.2*0.2*0.25 -> 34.375 | D40: =D8/1.2*0.2*0.25 -> 37.8125 | E40: =E8/1.2*0.2*0.25 -> 37.8125 | F40: =F8/1.2*0.2*0.25 -> 36.09375 | G40: =G8/1.2*0.2*0.25 -> 37.8125 | H40: =H8/1.2*0.2*0.25 -> 39.53125 | I40: =I8/1.2*0.2*0.25 -> 36.09375 | ... M40: =M8/1.2*0.2*0.25 -> 39.53125 | O40: =SUM(B40:M40) -> 448.59375
A41: TVA Collectée 10% | B41: =B7/1.1*0.1+B8/1.1*0.1*0.75 -> 1794.375 | C41: =C7/1.1*0.1+C8/1.1*0.1*0.75 -> 1631.25 | D41: =D7/1.1*0.1+D8/1.1*0.1*0.75 -> 1794.375 | E41: =E7/1.1*0.1+E8/1.1*0.1*0.75 -> 1794.375 | F41: =F7/1.1*0.1+F8/1.1*0.1*0.75 -> 1712.8125 | G41: =G7/1.1*0.1+G8/1.1*0.1*0.75 -> 1794.375 | H41: =H7/1.1*0.1+H8/1.1*0.1*0.75 -> 1875.9375 | I41: =I7/1.1*0.1+I8/1.1*0.1*0.75 -> 1712.8125 | ... M41: =M7/1.1*0.1+M8/1.1*0.1*0.75 -> 1875.9375 | O41: =SUM(B41:M41) -> 21287.813
A42: TVA collectée 5,5% | O42: =SUM(B42:M42) -> 0
A43: TVA déductible 20% | B43: =(B16/1.2*0.2)+(B19/1.2*0.2)+(B20/1.2*0.2)+(B21/1.2*0.2*0.25)+(B22/1.2*0.2)+(B25/1.2*0.2)+(B26/1.2*0.2)+(B27/1.2*0.2)+(B28/1.2*0.2)+(B30/1.2*0.2)+(B31/1.2*0.2) -> 356.77396 | C43: =(C16/1.2*0.2)+(C19/1.2*0.2)+(C20/1.2*0.2)+(C21/1.2*0.2*0.25)+(C22/1.2*0.2)+(C25/1.2*0.2)+(C26/1.2*0.2)+(C27/1.2*0.2)+(C28/1.2*0.2)+(C30/1.2*0.2)+(C31/1.2*0.2) -> 290.55208 | D43: =(D16/1.2*0.2)+(D19/1.2*0.2)+(D20/1.2*0.2)+(D21/1.2*0.2*0.25)+(D22/1.2*0.2)+(D25/1.2*0.2)+(D26/1.2*0.2)+(D27/1.2*0.2)+(D28/1.2*0.2)+(D30/1.2*0.2)+(D31/1.2*0.2) -> 398.44063 | E43: =(E16/1.2*0.2)+(E19/1.2*0.2)+(E20/1.2*0.2)+(E21/1.2*0.2*0.25)+(E22/1.2*0.2)+(E25/1.2*0.2)+(E26/1.2*0.2)+(E27/1.2*0.2)+(E28/1.2*0.2)+(E30/1.2*0.2)+(E31/1.2*0.2) -> 356.77396 | F43: =(F16/1.2*0.2)+(F19/1.2*0.2)+(F20/1.2*0.2)+(F21/1.2*0.2*0.25)+(F22/1.2*0.2)+(F25/1.2*0.2)+(F26/1.2*0.2)+(F27/1.2*0.2)+(F28/1.2*0.2)+(F30/1.2*0.2)+(F31/1.2*0.2) -> 302.82969 | G43: =(G16/1.2*0.2)+(G19/1.2*0.2)+(G20/1.2*0.2)+(G21/1.2*0.2*0.25)+(G22/1.2*0.2)+(G25/1.2*0.2)+(G26/1.2*0.2)+(G27/1.2*0.2)+(G28/1.2*0.2)+(G30/1.2*0.2)+(G31/1.2*0.2) -> 315.10729 | H43: =(H16/1.2*0.2)+(H19/1.2*0.2)+(H20/1.2*0.2)+(H21/1.2*0.2*0.25)+(H22/1.2*0.2)+(H25/1.2*0.2)+(H26/1.2*0.2)+(H27/1.2*0.2)+(H28/1.2*0.2)+(H30/1.2*0.2)+(H31/1.2*0.2) -> 369.05156 | I43: =(I16/1.2*0.2)+(I19/1.2*0.2)+(I20/1.2*0.2)+(I21/1.2*0.2*0.25)+(I22/1.2*0.2)+(I25/1.2*0.2)+(I26/1.2*0.2)+(I27/1.2*0.2)+(I28/1.2*0.2)+(I30/1.2*0.2)+(I31/1.2*0.2) -> 386.16302 | ... M43: =(M16/1.2*0.2)+(M19/1.2*0.2)+(M20/1.2*0.2)+(M21/1.2*0.2*0.25)+(M22/1.2*0.2)+(M25/1.2*0.2)+(M26/1.2*0.2)+(M27/1.2*0.2)+(M28/1.2*0.2)+(M30/1.2*0.2)+(M31/1.2*0.2) -> 327.3849 | O43: =SUM(B43:M43) -> 4077.788
A44: TVA Déductible 10% | O44: =SUM(B44:M44) -> 0
...

Sheet Trésorerie année 3
A1: Budget de trésorerie | B1: =Paramètres!$E$3 -> 2027
A2: Régime fiscal EURL
A3: Trésorerie début de mois | B3: ='Trésorerie année 2'!M51 -> 41328.61 | C3: =B51 -> 40626.03 | D3: =C51 -> 41405.743 | E3: =D51 -> 43416.904 | F3: =E51 -> 45063.218 | G3: =F51 -> 46634.565 | H3: =G51 -> 48617.485 | I3: =H51 -> 50340.436 | J3: =I51 -> 51796.72 | ... M3: =L51 -> 57223.938
B5: Janvier | C5: Février | D5: Mars | E5: Avril | F5: Mai | G5: Juin | H5: Juillet | I5: Août | J5: Septembre | K5: Octobre | L5: Novembre | M5: Décembre | O5: TOTAL
A6: Nb de jours ouvrables | B6: =NETWORKDAYS(DATE(Paramètres!$E$3,COLUMN()-1,1),EOMONTH(DATE(Paramètres!$E$3,COLUMN()-1,1),0)) -> 21 | C6: =NETWORKDAYS(DATE(Paramètres!$E$3,COLUMN()-1,1),EOMONTH(DATE(Paramètres!$E$3,COLUMN()-1,1),0)) -> 20 | D6: =NETWORKDAYS(DATE(Paramètres!$E$3,COLUMN()-1,1),EOMONTH(DATE(Paramètres!$E$3,COLUMN()-1,1),0)) -> 23 | E6: =NETWORKDAYS(DATE(Paramètres!$E$3,COLUMN()-1,1),EOMONTH(DATE(Paramètres!$E$3,COLUMN()-1,1),0)) -> 22 | F6: =NETWORKDAYS(DATE(Paramètres!$E$3,COLUMN()-1,1),EOMONTH(DATE(Paramètres!$E$3,COLUMN()-1,1),0)) -> 21 | G6: =NETWORKDAYS(DATE(Paramètres!$E$3,COLUMN()-1,1),EOMONTH(DATE(Paramètres!$E$3,COLUMN()-1,1),0)) -> 22 | H6: =NETWORKDAYS(DATE(Paramètres!$E$3,COLUMN()-1,1),EOMONTH(DATE(Paramètres!$E$3,COLUMN()-1,1),0)) -> 22 | I6: =NETWORKDAYS(DATE(Paramètres!$E$3,COLUMN()-1,1),EOMONTH(DATE(Paramètres!$E$3,COLUMN()-1,1),0)) -> 22 | ... M6: =NETWORKDAYS(DATE(Paramètres!$E$3,COLUMN()-1,1),EOMONTH(DATE(Paramètres!$E$3,COLUMN()-1,1),0)) -> 23 | O6: =SUM(B6:M6) -> 261
A7: Ventes repas | B7: =(Paramètres!$E$8*Paramètres!$E$4*'Trésorerie année 3'!B6) -> 20055.853 | C7: =(Paramètres!$E$8*Paramètres!$E$4*'Trésorerie année 3'!C6) -> 19100.813 | D7: =(Paramètres!$E$8*Paramètres!$E$4*'Trésorerie année 3'!D6) -> 21965.934 | E7: =(Paramètres!$E$8*Paramètres!$E$4*'Trésorerie année 3'!E6) -> 21010.894 | F7: =(Paramètres!$E$8*Paramètres!$E$4*'Trésorerie année 3'!F6) -> 20055.853 | G7: =(Paramètres!$E$8*Paramètres!$E$4*'Trésorerie année 3'!G6) -> 21010.894 | H7: =(Paramètres!$E$8*Paramètres!$E$4*'Trésorerie année 3'!H6) -> 21010.894 | I7: =(Paramètres!$E$8*Paramètres!$E$4*'Trésorerie année 3'!I6) -> 21010.894 | ... M7: =(Paramètres!$E$8*Paramètres!$E$4*'Trésorerie année 3'!M6) -> 21965.934 | O7: =SUM(B7:M7) -> 249265.6
A8: Ventes Boissons | B8: =Paramètres!$E$8*'Trésorerie année 3'!B6*Paramètres!$E$6*3 -> 945.945 | C8: =Paramètres!$E$8*'Trésorerie année 3'!C6*Paramètres!$E$6*3 -> 900.9 | D8: =Paramètres!$E$8*'Trésorerie année 3'!D6*Paramètres!$E$6*3 -> 1036.035 | E8: =Paramètres!$E$8*'Trésorerie année 3'!E6*Paramètres!$E$6*3 -> 990.99 | F8: =Paramètres!$E$8*'Trésorerie année 3'!F6*Paramètres!$E$6*3 -> 945.945 | G8: =Paramètres!$E$8*'Trésorerie année 3'!G6*Paramètres!$E$6*3 -> 990.99 | H8: =Paramètres!$E$8*'Trésorerie année 3'!H6*Paramètres!$E$6*3 -> 990.99 | I8: =Paramètres!$E$8*'Trésorerie année 3'!I6*Paramètres!$E$6*3 -> 990.99 | ... M8: =Paramètres!$E$8*'Trésorerie année 3'!M6*Paramètres!$E$6*3 -> 1036.035 | O8: =SUM(B8:M8) -> 11756.745
A9: Apport personnel - associés | O9: =SUM(B9:M9) -> 0
A10: Prêts et financements | O10: =SUM(B10:M10) -> 0
A11: Aides & Subventions | B11: ='Plan de financement initial'!H16+'Plan de financement initial'!H19+'Plan de financement initial'!H24 -> 0 | O11: =SUM(B11:M11) -> 0
A12: ENCAISSEMENTS | B12: =SUM(B7:B11) -> 21001.798 | C12: =SUM(C7:C11) -> 20001.713 | D12: =SUM(D7:D11) -> 23001.969 | E12: =SUM(E7:E11) -> 22001.884 | F12: =SUM(F7:F11) -> 21001.798 | G12: =SUM(G7:G11) -> 22001.884 | H12: =SUM(H7:H11) -> 22001.884 | I12: =SUM(I7:I11) -> 22001.884 | ... M12: =SUM(M7:M11) -> 23001.969 | O12: =SUM(B12:M12) -> 261022.35 | P12: =IF(O12=SUM(O7:O11),"ok","non") -> ok
A14: Immobilisations incorporelles | B14: 0 | C14: 0 | D14: 0 | E14: 0 | F14: 0 | G14: 0 | H14: 0 | I14: 0 | J14: 0 | K14: 0 | L14: 0 | M14: 0 | O14: =SUM(B14:M14) -> 0
A15: Immobilisations corporelles | B15: 0 | C15: =IF(C5=Paramètres!$C$14,Paramètres!$C$13,0) -> 0 | D15: =IF(D5=Paramètres!$C$14,Paramètres!$C$13,0) -> 0 | E15: =IF(E5=Paramètres!$C$14,Paramètres!$C$13,0) -> 0 | F15: 0 | G15: =IF(G5=Paramètres!$C$14,Paramètres!$C$13,0) -> 0 | H15: =IF(H5=Paramètres!$C$14,Paramètres!$C$13,0) -> 0 | I15: =IF(I5=Paramètres!$C$14,Paramètres!$C$13,0) -> 0 | J15: =IF(J5=Paramètres!$C$14,Paramètres!$C$13,0) -> 0 | K15: =IF(K5=Paramètres!$C$14,Paramètres!$C$13,0) -> 0 | L15: =IF(L5=Paramètres!$C$14,Paramètres!$C$13,0) -> 0 | M15: =IF(M5=Paramètres!$C$14,Paramètres!$C$13,0) -> 0 | O15: =SUM(B15:M15) -> 0
A16: IMMOBILISATIONS | B16: =SUM(B14:B15) -> 0 | C16: =SUM(C14:C15) -> 0 | D16: =SUM(D14:D15) -> 0 | E16: =SUM(E14:E15) -> 0 | F16: =SUM(F14:F15) -> 0 | G16: =SUM(G14:G15) -> 0 | H16: =SUM(H14:H15) -> 0 | I16: =SUM(I14:I15) -> 0 | ... M16: =SUM(M14:M15) -> 0 | O16: =SUM(B16:M16) -> 0 | P16: =IF(O16=SUM(O14:O15),"ok","non") -> ok
A18: Achats de MP | B18: =B7*Paramètres!$E$5 -> 7220.1071 | C18: =C7*Paramètres!$E$5 -> 6876.2925 | D18: =D7*Paramètres!$E$5 -> 7907.7364 | E18: =E7*Paramètres!$E$5 -> 7563.9218 | F18: =F7*Paramètres!$E$5 -> 7220.1071 | G18: =G7*Paramètres!$E$5 -> 7563.9218 | H18: =H7*Paramètres!$E$5 -> 7563.9218 | I18: =I7*Paramètres!$E$5 -> 7563.9218 | ... M18: =M7*Paramètres!$E$5 -> 7907.7364 | O18: =SUM(B18:M18) -> 89735.617
A19: Emballages | B19: =Paramètres!$E$7*Paramètres!$E$8*'Trésorerie année 3'!B6 -> 327.4425 | C19: =Paramètres!$E$7*Paramètres!$E$8*'Trésorerie année 3'!C6 -> 311.85 | D19: =Paramètres!$E$7*Paramètres!$E$8*'Trésorerie année 3'!D6 -> 358.6275 | E19: =Paramètres!$E$7*Paramètres!$E$8*'Trésorerie année 3'!E6 -> 343.035 | F19: =Paramètres!$E$7*Paramètres!$E$8*'Trésorerie année 3'!F6 -> 327.4425 | G19: =Paramètres!$E$7*Paramètres!$E$8*'Trésorerie année 3'!G6 -> 343.035 | H19: =Paramètres!$E$7*Paramètres!$E$8*'Trésorerie année 3'!H6 -> 343.035 | I19: =Paramètres!$E$7*Paramètres!$E$8*'Trésorerie année 3'!I6 -> 343.035 | ... M19: =Paramètres!$E$7*Paramètres!$E$8*'Trésorerie année 3'!M6 -> 358.6275 | O19: =SUM(B19:M19) -> 4069.6425
A20: Carburant | B20: =Paramètres!$E$9*Paramètres!$E$12*'Trésorerie année 3'!B6 -> 88.935 | C20: =Paramètres!$E$9*Paramètres!$E$12*'Trésorerie année 3'!C6 -> 84.7 | D20: =Paramètres!$E$9*Paramètres!$E$12*'Trésorerie année 3'!D6 -> 97.405 | E20: =Paramètres!$E$9*Paramètres!$E$12*'Trésorerie année 3'!E6 -> 93.17 | F20: =Paramètres!$E$9*Paramètres!$E$12*'Trésorerie année 3'!F6 -> 88.935 | G20: =Paramètres!$E$9*Paramètres!$E$12*'Trésorerie année 3'!G6 -> 93.17 | H20: =Paramètres!$E$9*Paramètres!$E$12*'Trésorerie année 3'!H6 -> 93.17 | I20: =Paramètres!$E$9*Paramètres!$E$12*'Trésorerie année 3'!I6 -> 93.17 | ... M20: =Paramètres!$E$9*Paramètres!$E$12*'Trésorerie année 3'!M6 -> 97.405 | O20: =SUM(B20:M20) -> 1105.335
A21: Achats marchandises (boissons) | B21: =B8*Paramètres!$E$6 -> 245.9457 | C21: =C8*Paramètres!$E$6 -> 234.234 | D21: =D8*Paramètres!$E$6 -> 269.3691 | E21: =E8*Paramètres!$E$6 -> 257.6574 | F21: =F8*Paramètres!$E$6 -> 245.9457 | G21: =G8*Paramètres!$E$6 -> 257.6574 | H21: =H8*Paramètres!$E$6 -> 257.6574 | I21: =I8*Paramètres!$E$6 -> 257.6574 | ... M21: =M8*Paramètres!$E$6 -> 269.3691 | O21: =SUM(B21:M21) -> 3056.7537
A22: Fluides (eau, électricité, gaz, etc.) | B22: =B7*0.05 -> 1002.7927 | C22: =C7*0.05 -> 955.04063 | D22: =D7*0.05 -> 1098.2967 | E22: =E7*0.05 -> 1050.5447 | F22: =F7*0.05 -> 1002.7927 | G22: =G7*0.05 -> 1050.5447 | H22: =H7*0.05 -> 1050.5447 | I22: =I7*0.05 -> 1050.5447 | ... M22: =M7*0.05 -> 1098.2967 | O22: =SUM(B22:M22) -> 12463.28
A23: Frais d'emplacement (AOT) | B23: =Paramètres!$E$10*'Trésorerie année 3'!B6 -> 3472.875 | C23: =Paramètres!$E$10*'Trésorerie année 3'!C6 -> 3307.5 | D23: =Paramètres!$E$10*'Trésorerie année 3'!D6 -> 3803.625 | E23: =Paramètres!$E$10*'Trésorerie année 3'!E6 -> 3638.25 | F23: =Paramètres!$E$10*'Trésorerie année 3'!F6 -> 3472.875 | G23: =Paramètres!$E$10*'Trésorerie année 3'!G6 -> 3638.25 | H23: =Paramètres!$E$10*'Trésorerie année 3'!H6 -> 3638.25 | I23: =Paramètres!$E$10*'Trésorerie année 3'!I6 -> 3638.25 | ... M23: =Paramètres!$E$10*'Trésorerie année 3'!M6 -> 3803.625 | O23: =SUM(B23:M23) -> 43162.875
A24: Loyer local labo | B24: 500 | C24: 500 | D24: 500 | E24: 500 | F24: 500 | G24: 500 | H24: 500 | I24: 500 | J24: 500 | K24: 500 | L24: 500 | M24: 500 | O24: =SUM(B24:M24) -> 6000
A25: Frais internet-téléphone | B25: =20 -> 20 | C25: 20 | D25: 20 | E25: 20 | F25: 20 | G25: 20 | H25: 20 | I25: 20 | J25: 20 | K25: 20 | L25: 20 | M25: 20 | O25: =SUM(B25:M25) -> 240
A26: Frais logiciel TPE | B26: =(B7+B8)*0.01 -> 210.01798 | C26: =(C7+C8)*0.01 -> 200.01713 | D26: =(D7+D8)*0.01 -> 230.01969 | E26: =(E7+E8)*0.01 -> 220.01884 | F26: =(F7+F8)*0.01 -> 210.01798 | G26: =(G7+G8)*0.01 -> 220.01884 | H26: =(H7+H8)*0.01 -> 220.01884 | I26: =(I7+I8)*0.01 -> 220.01884 | ... M26: =(M7+M8)*0.01 -> 230.01969 | O26: =SUM(B26:M26) -> 2610.2235
A27: Fournitures diverses | C27: 400 | E27: 300 | H27: 200 | K27: 100 | O27: =SUM(B27:M27) -> 1000
A28: Entretien / Maintenance | B28: 150 | C28: 150 | D28: 150 | E28: 150 | F28: 150 | G28: 150 | H28: 150 | I28: 150 | J28: 150 | K28: 150 | L28: 150 | M28: 150 | O28: =SUM(B28:M28) -> 1800
A29: Assurances (camion, local, RC) | B29: 225 | C29: 225 | D29: 225 | E29: 225 | F29: 225 | G29: 225 | H29: 225 | I29: 225 | J29: 225 | K29: 225 | L29: 225 | M29: 225 | O29: =SUM(B29:M29) -> 2700
A30: Publicité / Communication / Mkgt | D30: 500 | I30: 500 | O30: =SUM(B30:M30) -> 1000
A31: Honoraires (prestataires divers) | B31: =100 -> 100 | C31: 100 | D31: 100 | E31: 100 | F31: 100 | G31: 100 | H31: 100 | I31: 100 | J31: 100 | K31: 100 | L31: 100 | M31: 100 | O31: =SUM(B31:M31) -> 1200
A32: Mutuelle | B32: 100 | C32: 100 | D32: 100 | E32: 100 | F32: 100 | G32: 100 | H32: 100 | I32: 100 | J32: 100 | K32: 100 | L32: 100 | M32: 100 | O32: =SUM(B32:M32) -> 1200
A33: Salaires Bruts Gérant | B33: ='Trésorerie année 2'!B33*1.1 -> 2662 | C33: ='Trésorerie année 2'!C33*1.1 -> 2662 | D33: ='Trésorerie année 2'!D33*1.1 -> 2662 | E33: ='Trésorerie année 2'!E33*1.1 -> 2662 | F33: ='Trésorerie année 2'!F33*1.1 -> 2662 | G33: ='Trésorerie année 2'!G33*1.1 -> 2662 | H33: ='Trésorerie année 2'!H33*1.1 -> 2662 | I33: ='Trésorerie année 2'!I33*1.1 -> 2662 | ... M33: ='Trésorerie année 2'!M33*1.1 -> 2662 | O33: =SUM(B33:M33) -> 31944
A34: Charges sociales patronales Gérant | B34: =B33*0.45 -> 1197.9 | C34: =C33*0.45 -> 1197.9 | D34: =D33*0.45 -> 1197.9 | E34: =E33*0.45 -> 1197.9 | F34: =F33*0.45 -> 1197.9 | G34: =G33*0.45 -> 1197.9 | H34: =H33*0.45 -> 1197.9 | I34: =I33*0.45 -> 1197.9 | ... M34: =M33*0.45 -> 1197.9 | O34: =SUM(B34:M34) -> 14374.8
A35: Frais financiers (frais TC, î) | B35: 10 | C35: 10 | D35: 10 | E35: 10 | F35: 10 | G35: 10 | H35: 10 | I35: 10 | J35: 10 | K35: 10 | L35: 10 | M35: 10 | O35: =SUM(B35:M35) -> 120
A36: Échéances d'emprunt | B36: =IF(Paramètres!$C$15="",0,-PMT(Paramètres!$C$16/12,Paramètres!$C$17*12,Paramètres!$C$15)) -> 673.09456 | C36: =IF(Paramètres!$C$15="",0,-PMT(Paramètres!$C$16/12,Paramètres!$C$17*12,Paramètres!$C$15)) -> 673.09456 | D36: =IF(Paramètres!$C$15="",0,-PMT(Paramètres!$C$16/12,Paramètres!$C$17*12,Paramètres!$C$15)) -> 673.09456 | E36: =IF(Paramètres!$C$15="",0,-PMT(Paramètres!$C$16/12,Paramètres!$C$17*12,Paramètres!$C$15)) -> 673.09456 | F36: =IF(Paramètres!$C$15="",0,-PMT(Paramètres!$C$16/12,Paramètres!$C$17*12,Paramètres!$C$15)) -> 673.09456 | G36: =IF(Paramètres!$C$15="",0,-PMT(Paramètres!$C$16/12,Paramètres!$C$17*12,Paramètres!$C$15)) -> 673.09456 | H36: =IF(Paramètres!$C$15="",0,-PMT(Paramètres!$C$16/12,Paramètres!$C$17*12,Paramètres!$C$15)) -> 673.09456 | I36: =IF(Paramètres!$C$15="",0,-PMT(Paramètres!$C$16/12,Paramètres!$C$17*12,Paramètres!$C$15)) -> 673.09456 | ... M36: =IF(Paramètres!$C$15="",0,-PMT(Paramètres!$C$16/12,Paramètres!$C$17*12,Paramètres!$C$15)) -> 673.09456 | O36: =SUM(B36:M36) -> 8077.1348
A37: IS ou autres selon régime jurid | B37: ='CR pluriannuel '!E11 -> 2282.995 | O37: =SUM(B37:M37) -> 2282.995
A38: DECAISSEMENTS | B38: =SUM(B18:B37) -> 20489.106 | C38: =SUM(C18:C37) -> 18007.629 | D38: =SUM(D18:D37) -> 19903.074 | E38: =SUM(E18:E37) -> 19104.592 | F38: =SUM(F18:F37) -> 18206.111 | G38: =SUM(G18:G37) -> 18804.592 | H38: =SUM(H18:H37) -> 19004.592 | I38: =SUM(I18:I37) -> 19304.592 | ... M38: =SUM(M18:M37) -> 19403.074 | O38: =SUM(B38:M38) -> 228142.66 | P38: =IF(O38=SUM(O18:O37),"ok","non") -> ok
A40: TVA collectée 20% | B40: =B8/1.2*0.2*0.25 -> 39.414375 | C40: =C8/1.2*0.2*0.25 -> 37.5375 | D40: =D8/1.2*0.2*0.25 -> 43.168125 | E40: =E8/1.2*0.2*0.25 -> 41.29125 | F40: =F8/1.2*0.2*0.25 -> 39.414375 | G40: =G8/1.2*0.2*0.25 -> 41.29125 | H40: =H8/1.2*0.2*0.25 -> 41.29125 | I40: =I8/1.2*0.2*0.25 -> 41.29125 | ... M40: =M8/1.2*0.2*0.25 -> 43.168125 | O40: =SUM(B40:M40) -> 489.86438
A41: TVA Collectée 10% | B41: =B7/1.1*0.1+B8/1.1*0.1*0.75 -> 1887.7556 | C41: =C7/1.1*0.1+C8/1.1*0.1*0.75 -> 1797.8625 | D41: =D7/1.1*0.1+D8/1.1*0.1*0.75 -> 2067.5419 | E41: =E7/1.1*0.1+E8/1.1*0.1*0.75 -> 1977.6488 | F41: =F7/1.1*0.1+F8/1.1*0.1*0.75 -> 1887.7556 | G41: =G7/1.1*0.1+G8/1.1*0.1*0.75 -> 1977.6488 | H41: =H7/1.1*0.1+H8/1.1*0.1*0.75 -> 1977.6488 | I41: =I7/1.1*0.1+I8/1.1*0.1*0.75 -> 1977.6488 | ... M41: =M7/1.1*0.1+M8/1.1*0.1*0.75 -> 2067.5419 | O41: =SUM(B41:M41) -> 23462.106
A42: TVA collectée 5,5% | O42: =SUM(B42:M42) -> 0
A43: TVA déductible 20% | B43: =(B16/1.2*0.2)+(B19/1.2*0.2)+(B20/1.2*0.2)+(B21/1.2*0.2*0.25)+(B22/1.2*0.2)+(B25/1.2*0.2)+(B26/1.2*0.2)+(B27/1.2*0.2)+(B28/1.2*0.2)+(B30/1.2*0.2)+(B31/1.2*0.2) -> 326.77909 | C43: =(C16/1.2*0.2)+(C19/1.2*0.2)+(C20/1.2*0.2)+(C21/1.2*0.2*0.25)+(C22/1.2*0.2)+(C25/1.2*0.2)+(C26/1.2*0.2)+(C27/1.2*0.2)+(C28/1.2*0.2)+(C30/1.2*0.2)+(C31/1.2*0.2) -> 380.02771 | D43: =(D16/1.2*0.2)+(D19/1.2*0.2)+(D20/1.2*0.2)+(D21/1.2*0.2*0.25)+(D22/1.2*0.2)+(D25/1.2*0.2)+(D26/1.2*0.2)+(D27/1.2*0.2)+(D28/1.2*0.2)+(D30/1.2*0.2)+(D31/1.2*0.2) -> 436.94853 | E43: =(E16/1.2*0.2)+(E19/1.2*0.2)+(E20/1.2*0.2)+(E21/1.2*0.2*0.25)+(E22/1.2*0.2)+(E25/1.2*0.2)+(E26/1.2*0.2)+(E27/1.2*0.2)+(E28/1.2*0.2)+(E30/1.2*0.2)+(E31/1.2*0.2) -> 390.19715 | F43: =(F16/1.2*0.2)+(F19/1.2*0.2)+(F20/1.2*0.2)+(F21/1.2*0.2*0.25)+(F22/1.2*0.2)+(F25/1.2*0.2)+(F26/1.2*0.2)+(F27/1.2*0.2)+(F28/1.2*0.2)+(F30/1.2*0.2)+(F31/1.2*0.2) -> 326.77909 | G43: =(G16/1.2*0.2)+(G19/1.2*0.2)+(G20/1.2*0.2)+(G21/1.2*0.2*0.25)+(G22/1.2*0.2)+(G25/1.2*0.2)+(G26/1.2*0.2)+(G27/1.2*0.2)+(G28/1.2*0.2)+(G30/1.2*0.2)+(G31/1.2*0.2) -> 340.19715 | H43: =(H16/1.2*0.2)+(H19/1.2*0.2)+(H20/1.2*0.2)+(H21/1.2*0.2*0.25)+(H22/1.2*0.2)+(H25/1.2*0.2)+(H26/1.2*0.2)+(H27/1.2*0.2)+(H28/1.2*0.2)+(H30/1.2*0.2)+(H31/1.2*0.2) -> 373.53048 | I43: =(I16/1.2*0.2)+(I19/1.2*0.2)+(I20/1.2*0.2)+(I21/1.2*0.2*0.25)+(I22/1.2*0.2)+(I25/1.2*0.2)+(I26/1.2*0.2)+(I27/1.2*0.2)+(I28/1.2*0.2)+(I30/1.2*0.2)+(I31/1.2*0.2) -> 423.53048 | ... M43: =(M16/1.2*0.2)+(M19/1.2*0.2)+(M20/1.2*0.2)+(M21/1.2*0.2*0.25)+(M22/1.2*0.2)+(M25/1.2*0.2)+(M26/1.2*0.2)+(M27/1.2*0.2)+(M28/1.2*0.2)+(M30/1.2*0.2)+(M31/1.2*0.2) -> 353.6152 | O43: =SUM(B43:M43) -> 4375.4449
A44: TVA Déductible 10% | O44: =SUM(B44:M44) -> 0
...

Sheet CR pluriannuel 
C2: Régime fiscal eurl
B3: COMPTES DE RESULTAT PREVISIONNELS | D3: Prévisionnel | E3: Prévisionnel | F3: Prévisionnel
D5: ='Trésorerie année 1'!B1 -> 2025 | E5: =D5+1 -> 2026 | F5: =E5+1 -> 2027
D7: TOTAL | E7: TOTAL | F7: TOTAL
C8: Charges | D8: =SUM(D15,D42,D66,D100,D126,D142,D149,D160,D172,D176) -> 180723.32 | E8: =SUM(E15,E42,E66,E100,E126,E142,E149,E160,E172,E176) -> 199901.13 | F8: =SUM(F15,F42,F66,F100,F126,F142,F149,F160,F172,F176) -> 217712.24
C9: Produits | D9: =SUM(D183,D189,D190,D191,D192,D198,D202) -> 186318.41 | E9: =SUM(E183,E189,E190,E191,E192,E198,E202) -> 215121.09 | F9: =SUM(F183,F189,F190,F191,F192,F198,F202) -> 237070.38
C10: Résultat Net | D10: =D9-D8-D11 -> 4755.8238 | E10: =E9-E8-E11 -> 12936.972 | F10: =F9-F8-F11 -> 16454.42
C11: IS (15% jusqu'à 42500 euros et 25% au-delà) | D11: =IF(D9-D8>42500,((42500*0.15)+((D9-D8-42500)*0.25)),(D9-D8)*0.15) -> 839.26302 | E11: =IF(E9-E8>42500,((42500*0.15)+((E9-E8-42500)*0.25)),(E9-E8)*0.15) -> 2282.995 | F11: =IF(F9-F8>42500,((42500*0.15)+((F9-F8-42500)*0.25)),(F9-F8)*0.15) -> 2903.7213
B12: CHARGES | D12: TOTAL | E12: TOTAL | F12: TOTAL
B15: 60 | C15: ACHATS | D15: =SUM(D16,D19,D20,D23,D34,D38,D39) -> 80138.184 | E15: =SUM(E16,E19,E20,E23,E34,E38,E39) -> 93775.616 | F15: =SUM(F16,F19,F20,F23,F34,F38,F39) -> 105574.4
B16: 602 | C16: ACHATS STOCKES - AUTRES APPROVISIONNEMENTS | D16: =SUM(D17:D18) -> 66021.558 | E16: =SUM(E17:E18) -> 78236.451 | F16: =SUM(F17:F18) -> 88448.826
B17: 602200 | C17: Fournitures consommables | D17: ='Trésorerie année 1'!O18/1.055 -> 63085.308 | E17: ='Trésorerie année 2'!O18/1.055 -> 75006.576 | F17: ='Trésorerie année 3'!O18/1.055 -> 85057.457
B18: 602600 | C18: Emballages | D18: ='Trésorerie année 1'!O19/1.2 -> 2936.25 | E18: ='Trésorerie année 2'!O19/1.2 -> 3229.875 | F18: ='Trésorerie année 3'!O19/1.2 -> 3391.3688
B19: 603 | C19: VARIATIONS DE STOCKS DE MARCHANDISES et APPROVISIONNEMENTS | D19: 0 | E19: 0 | F19: 0
B20: 604 | C20: ACHATS PRESTATIONS DE SERVICE et D'ETUDES | D20: =SUM(D21:D22) -> 1709.55 | E20: =SUM(E21:E22) -> 1973.8125 | F20: =SUM(F21:F22) -> 2175.1862
B21: 604300 | C21: Achat de prestations | D21: ='Trésorerie année 1'!O26/1.2 -> 1709.55 | E21: ='Trésorerie année 2'!O26/1.2 -> 1973.8125 | F21: ='Trésorerie année 3'!O26/1.2 -> 2175.1862
B22: 604400 | C22: Hébergement de site internet (nom de domaine, etc.) | D22: 0 | E22: 0 | F22: 0
B23: 606 | C23: ACHATS NON STOCKES DE MATIERES ET FOURNITURES | D23: =SUM(D24,D29,D32:D33) -> 10334.167 | E23: =SUM(E24,E29,E32:E33) -> 11091.177 | F23: =SUM(F24,F29,F32:F33) -> 12140.513
B24: 606100 | C24: Fournitures non stockables (fluides) | D24: =SUM(D25:D28) -> 8917.5 | E24: =SUM(E25:E28) -> 10257.844 | F24: =SUM(F25:F28) -> 11307.179
B25: 606 110 | C25: Eau | D25: =('Trésorerie année 1'!O22/3)/1.2 -> 2718.75 | E25: =('Trésorerie année 2'!O22/3)/1.2 -> 3140.1563 | F25: =('Trésorerie année 3'!O22/3)/1.2 -> 3462.0223
B26: 606 120 | C26: Electricité | D26: =('Trésorerie année 1'!O22/3)/1.2 -> 2718.75 | E26: =('Trésorerie année 2'!O22/3)/1.2 -> 3140.1563 | F26: =('Trésorerie année 3'!O22/3)/1.2 -> 3462.0223
B27: 606 130 | C27: Gaz | D27: =('Trésorerie année 1'!O22/3)/1.2 -> 2718.75 | E27: =('Trésorerie année 2'!O22/3)/1.2 -> 3140.1563 | F27: =('Trésorerie année 3'!O22/3)/1.2 -> 3462.0223
B28: 606 140 | C28: Carburant | D28: =('Trésorerie année 1'!O20)/1.2 -> 761.25 | E28: =('Trésorerie année 2'!O20)/1.2 -> 837.375 | F28: =('Trésorerie année 3'!O20)/1.2 -> 921.1125
B29: 606 300 | C29: Fournitures d'entretien et de petit équipement | D29: =SUM(D30:D31) -> 0 | E29: =SUM(E30:E31) -> 0 | F29: =SUM(F30:F31) -> 0
B30: 606310 | C30: Fournitures d'entretien | D30: 0 | E30: 0 | F30: 0
B31: 606 320 | C31: Fournitures de petit équipement | D31: 0 | E31: 0 | F31: 0
B32: 606400 | C32: Fournitures administratives | D32: 0 | E32: 0 | F32: 0
B33: 606800 | C33: Autres matières et fournitures diverses | D33: =('Trésorerie année 1'!O27)/1.2 -> 1416.6667 | E33: =('Trésorerie année 2'!O27)/1.2 -> 833.33333 | F33: =('Trésorerie année 3'!O27)/1.2 -> 833.33333
B34: 607 | C34: ACHATS DE MARCHANDISES | D34: =SUM(D35:D37) -> 2072.909 | E34: =SUM(E35:E37) -> 2474.1752 | F34: =SUM(F35:F37) -> 2809.8713
B35: 607100 | C35: Achats de marchandises - taux normal tva 20% | D35: =('Trésorerie année 1'!O21*0.25)/1.2 -> 469.8 | E35: =('Trésorerie année 2'!O21*0.25)/1.2 -> 560.74219 | F35: =('Trésorerie année 3'!O21*0.25)/1.2 -> 636.82369
B36: 607200 | C36: Achats de marchandises - taux intermédiaire 10% | D36: 0 | E36: 0 | F36: 0
B37: 607310 | C37: Achats de marchandises - taux réduit de 5,5% | D37: =('Trésorerie année 1'!O21*0.75)/1.055 -> 1603.109 | E37: =('Trésorerie année 2'!O21*0.75)/1.055 -> 1913.4331 | F37: =('Trésorerie année 3'!O21*0.75)/1.055 -> 2173.0477
B38: 608 | C38: FRAIS ACCESSOIRES D'ACHATS | D38: 0 | E38: 0 | F38: 0
B39: 609 | C39: RABAIS, REMISES, RISTOURNES OBTENUS SUR ACHATS | D39: =SUM(D40:D41) -> 0 | E39: =SUM(E40:E41) -> 0 | F39: =SUM(F40:F41) -> 0
B40: 609400 | C40: Rabais, Remises et Ristounes obtenus sur achats prestations de services | D40: 0 | E40: 0 | F40: 0
B41: 609700 | C41: Rabais, Remises et Ristounes obtenus sur achats de marchandises | D41: 0 | E41: 0 | F41: 0
B42: 61 | C42: SERVICES EXTERIEURS | D42: =SUM(D43,D44,D47,D50,D51,D56,D60,D61,D65) -> 10200 | E42: =SUM(E43,E44,E47,E50,E51,E56,E60,E61,E65) -> 10200 | F42: =SUM(F43,F44,F47,F50,F51,F56,F60,F61,F65) -> 10200
B43: 611 | C43: SOUS TRAITANCE GENERALE | D43: 0 | E43: 0 | F43: 0
B44: 612 | C44: REDEVANCES CREDIT BAIL | D44: =SUM(D45:D46) -> 0 | E44: =SUM(E45:E46) -> 0 | F44: =SUM(F45:F46) -> 0
B45: 612 200 | C45: Crédit-bail mobilier | D45: 0 | E45: 0 | F45: 0
...

Sheet Bilan année 1
D2: Bilan au 31/12/2025
B5: ACTIF | G5: PASSIF
B6: ACTIF IMMOBILISE | D6: BRUT | E6: AMORT. (28) & DEP (29) | F6: NET | G6: CAPITAUX PROPRES | I6: NET
B7: 20 | C7: Immobilisations Incorporelles | D7: =SUM(D8:D12) -> 1666.6667 | E7: =SUM(E8:E12) -> 416.66667 | F7: =D7-E7 -> 1250 | G7: 101 | H7: Capital | I7: ='Plan de financement initial'!H7 -> 22000
B8: 201 | C8: Frais d'établissement | D8: =('Plan de financement initial'!D7)/1.2 -> 1041.6667 | E8: =D8/5 -> 208.33333 | F8: =D8-E8 -> 833.33333 | G8: 1061 | H8: Réserve légale | I8: 0
B9: 203 | C9: Frais de recherche & développement | D9: 0 | E9: 0 | F9: =D9-E9 -> 0 | G9: 1063 | H9: Réserve statutaire | I9: 0
B10: 205 | C10: Concesions, brevets | D10: ='Plan de financement initial'!D16 -> 0 | E10: 0 | F10: =D10-E10 -> 0 | G10: 1064 | H10: Réserves réglementées | I10: 0
B11: 207 | C11: Fonds commercial | D11: ='Plan de financement initial'!D19 -> 0 | E11: 0 | F11: =D11-E11 -> 0 | G11: 1068 | H11: Autres Réserves | I11: 0
B12: 208 | C12: Autres immobilisations incorporelles | D12: =('Plan de financement initial'!D17+'Plan de financement initial'!D18)/1.2 -> 625 | E12: =D12/3 -> 208.33333 | F12: =D12-E12 -> 416.66667 | G12: 11 | H12: Report à nouveau (créditeur ou débiteur) | I12: 0
B13: 21 | C13: Immobilisations Corporelles | D13: =SUM(D14:D17) -> 40000 | E13: =SUM(E14:E17) -> 8000 | F13: =D13-E13 -> 32000 | G13: 12 | H13: Résultat de l'exercice | I13: ='CR pluriannuel '!D10 -> 4755.8238
B14: 211 | C14: Terrains | D14: ='Plan de financement initial'!D27 -> 0 | E14: 0 | F14: =D14-E14 -> 0 | G14: 13 | H14: Subvention d'investissement | I14: 0
B15: 213 | C15: Constructions | D15: ='Plan de financement initial'!D28+'Plan de financement initial'!D22 -> 0 | E15: 0 | F15: =D15-E15 -> 0 | G15: 14 | H15: Provisions réglementées | I15: 0
B16: 215 | C16: Installations techniques, matériel et outillage industriel | D16: =('Plan de financement initial'!D25+'Plan de financement initial'!D24+'Plan de financement initial'!D26)/1.2 -> 7500 | E16: =D16/5 -> 1500 | F16: =D16-E16 -> 6000 | G16: Total I | I16: =SUM(I7:I15) -> 26755.824
B17: 218 | C17: Autres immobilisations corporelles | D17: =('Plan de financement initial'!D23)/1.2 -> 32500 | E17: =D17/5 -> 6500 | F17: =D17-E17 -> 26000 | G17: 151 | H17: Provisions pour risques | I17: 0
C18: Immobilisations financières | D18: =SUM(D19:D23) -> 0 | E18: =SUM(E19:E23) -> 0 | F18: =D18-E18 -> 0 | G18: 157 | H18: Provisions pour charges | I18: 0
B19: 261 | C19: Titres de Participations | D19: 0 | E19: 0 | F19: =D19-E19 -> 0 | G19: 158 | H19: Autres Provisions pour charges | I19: 0
B20: 267 | C20: Créances rattachées à des participations | D20: 0 | E20: 0 | F20: =D20-E20 -> 0 | G20: Total II | I20: =SUM(I17:I19) -> 0
B21: 271 | C21: Autres titres immobilisés | D21: 0 | E21: 0 | F21: =D21-E21 -> 0 | G21: PASSIF CIRCULANT | I21: NET
B22: 274 | C22: Prêts | D22: 0 | E22: 0 | G22: 163 | H22: Autres emprunts obligataires | I22: 0
B23: 276 | C23: Autres créances immobilisées | D23: ='Plan de financement initial'!D30+'Plan de financement initial'!D31 -> 0 | E23: 0 | F23: =D23-E23 -> 0 | G23: 164 | H23: Emprunts et dettes établissements de crédit (1) | I23: =Emprunt!J29 -> 30108.004
B24: Total I | D24: =D7+D13+D18 -> 41666.667 | E24: =E7+E13+E18 -> 8416.6667 | F24: =F7+F13+F18 -> 33250 | G24: 166 | H24: Participation des salariés aux résultats | I24: 0
B25: ACTIF CIRCULANT | D25: BRUT | E25: DEP. (39/49/59) | F25: NET | G25: 168 | H25: Autres emprunts et dettes assimilées financières | I25: 0
B26: 31 | C26: Stocks MP | D26: 0 | E26: 0 | F26: =D26-E26 -> 0 | G26: 401/403 | H26: Dettes fournisseurs | I26: 0
B27: 32 | C27: Stocks autres approv. | D27: 0 | E27: 0 | F27: =D27-E27 -> 0 | G27: 404 | H27: Dette fournisseurs immobilisations | I27: 0
B28: 33/34 | C28: Stocks En-cours | D28: 0 | E28: 0 | F28: =D28-E28 -> 0 | G28: 419 | H28: Avances et acomptes reçus | I28: 0
B29: 35 | C29: Stocks de Produits | D29: 0 | E29: 0 | F29: =D29-E29 -> 0 | G29: 42 | H29: Dettes charges de personnel | I29: 0
B30: 37 | C30: Stocks de Marchandises | D30: 0 | E30: 0 | F30: =D30-E30 -> 0 | G30: 43 | H30: Dettes de sécurité sociale et autres org soc | I30: 0
B31: 409 | C31: Avances et acomptes versés | D31: 0 | E31: 0 | F31: =D31-E31 -> 0 | G31: 44 | H31: Dettes de l'Etat et CP | I31: ='Trésorerie année 1'!M47+'CR pluriannuel '!D11 -> 1892.5446
B32: 411/413/416/418 | C32: Créances clients | D32: 0 | E32: 0 | F32: =D32-E32 -> 0 | G32: 46 | H32: Autres dettes | I32: 0
B33: 50 | C33: Valeurs mobilières de placement | D33: 0 | E33: 0 | F33: =D33-E33 -> 0 | G33: 487 | H33: Produits constatés d'avance | I33: 0
B34: 51/53 | C34: Disponibilités | D34: ='Trésorerie année 1'!M51 -> 25506.372 | E34: 0 | F34: =D34-E34 -> 25506.372
B35: 486 | C35: Charges constatées d'avance | E35: 0 | F35: =D35-E35 -> 0
B36: Total II | D36: =SUM(D26:D35) -> 25506.372 | E36: =SUM(E26:E35) -> 0 | F36: =SUM(F26:F35) -> 25506.372 | G36: Total III | I36: =SUM(I22:I33) -> 32000.548
B37: TOTAL GENERAL (I + II) | D37: =D24+D36 -> 67173.039 | E37: =E24+E36 -> 8416.6667 | F37: =F24+F36 -> 58756.372 | G37: TOTAL GENERAL (I + II + III) | I37: =I16+I20+I36 -> 58756.372
I39: =F37-I37 -> 0
H41: (1) dont soldes créditeurs de banques :

Sheet Bilan année 2
D2: Bilan au 31/12/2026
B5: ACTIF | G5: PASSIF
B6: ACTIF IMMOBILISE | D6: BRUT | E6: AMORT. (28) & DEP (29) | F6: NET | G6: CAPITAUX PROPRES | I6: NET
B7: 20 | C7: Immobilisations Incorporelles | D7: =SUM(D8:D12) -> 1666.6667 | E7: =SUM(E8:E12) -> 833.33333 | F7: =D7-E7 -> 833.33333 | G7: 101 | H7: Capital | I7: ='Plan de financement initial'!H7 -> 22000
B8: 201 | C8: Frais d'établissement | D8: =('Plan de financement initial'!D7)/1.2 -> 1041.6667 | E8: =(D8/5)*2 -> 416.66667 | F8: =D8-E8 -> 625 | G8: 1061 | H8: Réserve légale | I8: ='Bilan année 1'!I13 -> 4755.8238
B9: 203 | C9: Frais de recherche & développement | D9: 0 | E9: 0 | F9: =D9-E9 -> 0 | G9: 1063 | H9: Réserve statutaire | I9: 0
B10: 205 | C10: Concesions, brevets | D10: ='Plan de financement initial'!D16 -> 0 | E10: 0 | F10: =D10-E10 -> 0 | G10: 1064 | H10: Réserves réglementées | I10: 0
B11: 207 | C11: Fonds commercial | D11: ='Plan de financement initial'!D19 -> 0 | E11: 0 | F11: =D11-E11 -> 0 | G11: 1068 | H11: Autres Réserves | I11: 0
B12: 208 | C12: Autres immobilisations incorporelles | D12: =('Plan de financement initial'!D17+'Plan de financement initial'!D18)/1.2 -> 625 | E12: =(D12/3)*2 -> 416.66667 | F12: =D12-E12 -> 208.33333 | G12: 11 | H12: Report à nouveau (créditeur ou débiteur) | I12: 0
B13: 21 | C13: Immobilisations Corporelles | D13: =SUM(D14:D17) -> 40000 | E13: =SUM(E14:E17) -> 16000 | F13: =D13-E13 -> 24000 | G13: 12 | H13: Résultat de l'exercice | I13: ='CR pluriannuel '!E10 -> 12936.972
B14: 211 | C14: Terrains | D14: ='Plan de financement initial'!D27 -> 0 | E14: 0 | F14: =D14-E14 -> 0 | G14: 13 | H14: Subvention d'investissement | I14: 0
B15: 213 | C15: Constructions | D15: ='Plan de financement initial'!D28+'Plan de financement initial'!D22 -> 0 | E15: 0 | F15: =D15-E15 -> 0 | G15: 14 | H15: Provisions réglementées | I15: 0
B16: 215 | C16: Installations techniques, matériel et outillage industriel | D16: =('Plan de financement initial'!D25+'Plan de financement initial'!D24+'Plan de financement initial'!D26)/1.2 -> 7500 | E16: =(D16/5)*2 -> 3000 | F16: =D16-E16 -> 4500 | G16: Total I | I16: =SUM(I7:I15) -> 39692.796
B17: 218 | C17: Autres immobilisations corporelles | D17: =('Plan de financement initial'!D23)/1.2 -> 32500 | E17: =(D17/5)*2 -> 13000 | F17: =D17-E17 -> 19500 | G17: 151 | H17: Provisions pour risques | I17: 0
C18: Immobilisations financières | D18: =SUM(D19:D23) -> 0 | E18: =SUM(E19:E23) -> 0 | F18: =D18-E18 -> 0 | G18: 157 | H18: Provisions pour charges | I18: 0
B19: 261 | C19: Titres de Participations | D19: 0 | E19: 0 | F19: =D19-E19 -> 0 | G19: 158 | H19: Autres Provisions pour charges | I19: 0
B20: 267 | C20: Créances rattachées à des participations | D20: 0 | E20: 0 | F20: =D20-E20 -> 0 | G20: Total II | I20: =SUM(I17:I19) -> 0
B21: 271 | C21: Autres titres immobilisés | D21: 0 | E21: 0 | F21: =D21-E21 -> 0 | G21: PASSIF CIRCULANT | I21: NET
B22: 274 | C22: Prêts | D22: 0 | E22: 0 | G22: 163 | H22: Autres emprunts obligataires | I22: 0
B23: 276 | C23: Autres créances immobilisées | D23: ='Plan de financement initial'!D30+'Plan de financement initial'!D31 -> 0 | E23: 0 | F23: =D23-E23 -> 0 | G23: 164 | H23: Emprunts et dettes établissements de crédit (1) | I23: =Emprunt!J41 -> 22970.88
B24: Total I | D24: =D7+D13+D18 -> 41666.667 | E24: =E7+E13+E18 -> 16833.333 | F24: =F7+F13+F18 -> 24833.333 | G24: 166 | H24: Participation des salariés aux résultats | I24: 0
B25: ACTIF CIRCULANT | D25: BRUT | E25: DEP. (39/49/59) | F25: NET | G25: 168 | H25: Autres emprunts et dettes assimilées financières | I25: 0
B26: 31 | C26: Stocks MP | D26: 0 | E26: 0 | F26: =D26-E26 -> 0 | G26: 401/403 | H26: Dettes fournisseurs | I26: 0
